<?xml version='1.0'?>
<sdf version='1.6'>
    <model name='arm'>
        <link name='base'>
            <pose>0 0 0.05 0 0 0</pose>
            <collision name='collision'>
                <geometry>
                    <cylinder>
                        <radius>.5</radius>
                        <length>.1</length>
                    </cylinder>
                </geometry>
            </collision>

            <visual name='visual'>
                <geometry>
                    <cylinder>
                        <radius>.5</radius>
                        <length>.1</length>
                    </cylinder>
                </geometry>
            </visual>
        </link>
        <joint name="base_arm1" type="revolute">
            <parent>base</parent>
            <child>arm1</child>
            <pose>0 0 -0.025 0 0</pose>
            <axis>
                <xyz>0 0 1</xyz>
            </axis>
        </joint>
        <link name='arm1'>
            <gravity>0</gravity>
            <pose>0 0 0.125 0 0 0</pose>

            <collision name='collision'>
                <geometry>
                    <cylinder>
                        <radius>.1</radius>
                        <length>.05</length>
                    </cylinder>
                </geometry>
            </collision>

            <visual name='visual'>
                <geometry>
                    <cylinder>
                        <radius>.1</radius>
                        <length>.05</length>
                    </cylinder>
                </geometry>
            </visual>
        </link>
        <joint name="arm1_arm2" type="revolute">
            <parent>arm1</parent>
            <child>arm2</child>
            <pose>0 0 -1 0 0 0</pose>
            <axis>
                <xyz>1 0 0</xyz>
            </axis>
        </joint>
        <link name='arm2'>
            <gravity>0</gravity>
            <pose>0 0 1.15 0 0 0</pose>

            <collision name='collision'>
                <geometry>
                    <cylinder>
                        <radius>.05</radius>
                        <length>2</length>
                    </cylinder>
                </geometry>
            </collision>

            <visual name='visual'>
                <geometry>
                    <cylinder>
                        <radius>.05</radius>
                        <length>2</length>
                    </cylinder>
                </geometry>
            </visual>
        </link>
        <joint name="arm2_arm3" type="revolute">
            <parent>arm2</parent>
            <child>arm3</child>
            <pose>0 0 -0.5 0 0 0</pose>
            <axis>
                <xyz>1 0 0</xyz>
            </axis>
        </joint>
        <link name='arm3'>
            <gravity>0</gravity>
            <pose>0 0 2.65 0 0 0</pose>

            <collision name='collision'>
                <geometry>
                    <cylinder>
                        <radius>.05</radius>
                        <length>1</length>
                    </cylinder>
                </geometry>
            </collision>

            <visual name='visual'>
                <geometry>
                    <cylinder>
                        <radius>.05</radius>
                        <length>1</length>
                    </cylinder>
                </geometry>
            </visual>
        </link>
        <joint name="arm3_arm4" type="revolute">
            <parent>arm3</parent>
            <child>arm4</child>
            <pose>0 0 -0.25 0 0 0</pose>
            <axis>
                <xyz>1 0 0</xyz>
            </axis>
        </joint>
        <link name='arm4'>
            <gravity>0</gravity>
            <pose>0 0 3.4 0 0 0</pose>

            <collision name='collision'>
                <geometry>
                    <cylinder>
                        <radius>.05</radius>
                        <length>.5</length>
                    </cylinder>
                </geometry>
            </collision>

            <visual name='visual'>
                <geometry>
                    <cylinder>
                        <radius>.05</radius>
                        <length>.5</length>
                    </cylinder>
                </geometry>
            </visual>
        </link>
        <plugin name="publisher" filename="libPublisher.so"/>
        <plugin name="subscriber" filename="libSubscriber.so"/>
    </model>
</sdf>